<?xml version="1.0" ?>
<robot name="mybot">
  <joint name="mybot__link_0_JOINT_0" type="revolute">
    <parent link="mybot__base_link"/>
    <child link="mybot__wheel_1"/>
    <origin rpy="0  0  0" xyz="0 0 0"/>
    <axis xyz="0  0  1"/>
    <limit effort="-1.0" lower="-1.79769e+308" upper="1.79769e+308" velocity="-1.0"/>
  </joint>
  <joint name="mybot__link_0_JOINT_1" type="revolute">
    <parent link="mybot__base_link"/>
    <child link="mybot__wheel_2"/>
    <origin rpy="0  0  0" xyz="0 0 0"/>
    <axis xyz="0  0  1"/>
    <limit effort="-1.0" lower="-1.79769e+308" upper="1.79769e+308" velocity="-1.0"/>
  </joint>
  <joint name="mybot__link_0_JOINT_2" type="revolute">
    <parent link="mybot__base_link"/>
    <child link="mybot__wheel_3"/>
    <origin rpy="0  0  0" xyz="0 0 0"/>
    <axis xyz="0  0  1"/>
    <limit effort="-1.0" lower="-1.79769e+308" upper="1.79769e+308" velocity="-1.0"/>
  </joint>

  <link name="mybot__base_link">
    <inertial>
      <mass value="5"/>
      <origin rpy="0  0  0" xyz="0  0  0"/>
      <inertia ixx="0.0541667" ixy="0" ixz="0" iyy="0.0541667" iyz="0" izz="0.1"/>
    </inertial>
    <collision name="mybot__collision">
      <origin rpy="0  0       0" xyz="0   0   0.15"/>
      <geometry>
        <cylinder length="0.1" radius="0.2"/>
      </geometry>
    </collision>
    <visual name="mybot__visual">
      <origin rpy="0  0    0" xyz="0   0   0.15"/>
      <geometry>
        <cylinder length="0.1" radius="0.2"/>
      </geometry>
    </visual>
  </link>
  <link name="mybot__wheel_1">
    <inertial>
      <mass value="1"/>
      <origin rpy="1.57079 3e-06 3.14159" xyz="-0.006021 0.25 0.15"/>
      <inertia ixx="0.145833" ixy="0" ixz="0" iyy="0.145833" iyz="0" izz="0.125"/>
    </inertial>
    <collision name="mybot__collision">
      <origin rpy="1.57079 3e-06 3.14159" xyz="-0.006021 0.25 0.15"/>
      <geometry>
        <cylinder length="0.1" radius="0.15"/>
      </geometry>
    </collision>
    <visual name="mybot__visual">
      <origin rpy="1.57079 3e-06 3.14159" xyz="-0.006021 0.25 0.15"/>
      <geometry>
        <cylinder length="0.1" radius="0.15"/>
      </geometry>
    </visual>
  </link>
  <link name="mybot__wheel_2">
    <inertial>
      <mass value="1"/>
      <origin rpy="1.5708 -0 1" xyz="0.210479 -0.125 0.15 "/>
      <inertia ixx="0.145833" ixy="0" ixz="0" iyy="0.145833" iyz="0" izz="0.125"/>
    </inertial>
    <collision name="mybot__collision">
      <origin rpy="1.5708 -0 1" xyz="0.210479 -0.125 0.15 "/>
      <geometry>
        <cylinder length="0.1" radius="0.15"/>
      </geometry>
    </collision>
    <visual name="mybot__visual">
      <origin rpy="1.5708 -0 1" xyz="0.210479 -0.125 0.15 "/>
      <geometry>
        <cylinder length="0.1" radius="0.15"/>
      </geometry>
    </visual>
  </link>
    <link name="mybot__wheel_3">
    <inertial>
      <mass value="1"/>
      <origin rpy="1.5708 -0 -1" xyz="-0.2165 -0.125 0.15 "/>
      <inertia ixx="0.145833" ixy="0" ixz="0" iyy="0.145833" iyz="0" izz="0.125"/>
    </inertial>
    <collision name="mybot__collision">
      <origin rpy="1.5708 -0 -1" xyz="-0.2165 -0.125 0.15 "/>
      <geometry>
        <cylinder length="0.1" radius="0.15"/>
      </geometry>
    </collision>
    <visual name="mybot__visual">
      <origin rpy="1.5708 -0 -1" xyz="-0.2165 -0.125 0.15 "/>
      <geometry>
        <cylinder length="0.1" radius="0.15"/>
      </geometry>
    </visual>
  </link>
 
 <gazebo>
    <plugin name="object_controller" filename="libgazebo_ros_planar_move.so">
      <commandTopic>cmd_vel</commandTopic>
      <odometryTopic>odom</odometryTopic>
      <odometryFrame>odom</odometryFrame>
      <odometryRate>20.0</odometryRate>
      <robotBaseFrame>base_footprint</robotBaseFrame>
    </plugin>
</gazebo>
 
 
 
  
  
</robot>
